Workbook
Name Chemical_Comp._A105_A350: Tablo11[]
Name Fitting_TAblosu: Fitting_Flanş[]
Name MSS_SP_44_Pressure_Temperature_Ratings: Tablo48[]
Name MSS_SP_44_Ratings: Tablo48[]
Name Chemical_Comp._A105_A350: Tablo11[]
Name Fitting_TAblosu: Fitting_Flanş[]
Name MSS_SP_44_Pressure_Temperature_Ratings: Tablo48[]
Name MSS_SP_44_Ratings: Tablo48[]
Name ASTM_A350_LF2: 'Low Temp. Pipe&Fittings'!$AW$52:$AW$54

Sheet Et Kalınlığı Hesaplama
R1: 2 | S1: 3
B2: Et Kalınlığı Hesaplama | R2: =CHOOSE(R1,"Station","Pipeline","Pig Or Valve Station") | S2: =CHOOSE(S1,0.4,0.5, 0.6,0.72,0.8)
B3: Corr. All. | C3: 0 | D3: (mm)
B4: S= | C4: 42100 | D4: (psi) | E4: =VLOOKUP(C4,'Boru SMYS Tablosu'!$D$4:H16,5,0) | F4: (mpa)
B5: D= | C5: 4" | D5: (inch) | E5: =VLOOKUP(C5,Tablo2[[ÇAP inch]:[ÇAP mm]],2,0) | F5: (mm)
B6: F= | C6: =$S$2
B7: E= | C7: 1
B8: T= | C8: 1
B9: P= | C9: 75 | D9: (bar) | E9: =C9/10 | F9: (mpa)
B10: ="Required Pipe Thickness (Botaş) for"&"-"&R2
B11: F=0,72 | C11: F=0,60 | D11: F=0,50 | E11: F=0,50 | F11: F=0,50
B12: =VLOOKUP(C5,Tablo244[],6,0) | C12: =VLOOKUP(C5,Tablo244[],8,0) | D12: =VLOOKUP(C5,Tablo244[],10,0) | E12: =VLOOKUP(C5,Tablo244[],12,0) | F12: =VLOOKUP(C5,Tablo244[],14,0)
B13: Required Pipe Thickness (ASME B31.8)
B14: =IF(R1=2,(E9*E5/(2*E4*C6*C7*C8)),(IF(E5<168.3,((E9*E5/(2*E4*C6*C7*C8))+C3)*1.125, (E9*E5/(2*E4*C6*C7*C8))+C3))) | F14: (mm)
B15: Selected Pipe Thickness ASME 36.10
B16: =VLOOKUP('ASME B36.10'!$B$48,'ASME B36.10'!$B$50:AU84,'ASME B36.10'!$A$48,FALSE) | F16: (mm) | G16: NOTE:
B17: Negative Tolerans | D17: =B16*0.875 | G17: =IF(R1=2,"Please Choose F=0,5 - 0,6 - 0,72 or 0,8","Please Choose F 0,5")
G18: =IF(R1=1,IF(S1>2,"Wrong F Factor",""),IF(R1=3,IF(S1>2,"Wrong F Factor",""),""))

Sheet Boru Seçim-Kontrol Aracı
E1: Boru akma değerleri Mpa olarak alındığında TEST Basıncı | T1: BOTAŞ | U1: 2 | W1: 1
A2: Kontrol Edilecek Boru: | D2: BOTAŞ | S2: Hidrostatik Test Hacmi | T2: ASME B36.10 | U2: =CHOOSE(U1,0.4,0.5, 0.6,0.72,0.8) | W2: =CHOOSE(W1,"Station","Pipeline") | AA2: Çap | AB2: Uzunluk | AC2: Hacim | AD2: Sütun1 | AF2: 0.4
E3: =20*G24*E10/E8 | F3: =20*G24*F10/E8 | G3: =20*G24*G10/E8 | H3: =20*G24*H10/E8 | I3: =20*G24*I10/E8 | J3: Bar | AA3: =E8 | AB3: 3217.6 | AC3: =3.14*POWER((AA3-2*E10)/1000,2)*AB3/4 | AD3: m3 | AF3: 0.5
I4: Et Kalınlığı(mm) | J4: Manuel Hydro Test (Bar) | AA4: =E8 | AB4: 333.25 | AC4: =3.14*POWER((AA4-2*F10)/1000,2)*AB4/4 | AD4: m3 | AF4: 0.6
I5: 3.6 | J5: =2*J13*J10/J8/14.50733 | AA5: =E8 | AB5: 0 | AC5: =3.14*POWER((AA5-2*G10)/1000,2)*AB5/4 | AD5: m3 | AF5: 0.72
B6: BORU SEÇİM ARACI | E6: OTOMATİK SEÇİM | J6: EL İLE SEÇİM | M6: Hot-Tap Sınır Basıncı (Bar) (Hot-Tap Şartnamesine Göre) | AC6: =SUM(AC3:AC5) | AF6: 0.8
B7: ÇAP (inch) | E7: 48" | J7: 18" | M7: 0,72 (Hat) | N7: 0,6 (Hat) | O7: 0,5 (Hat)
B8: ÇAP (mm) | E8: =VLOOKUP(E7,Tablo2[[ÇAP inch]:[MALZEME]],2,0) | J8: =VLOOKUP(J7,Tablo2[[ÇAP inch]:[MALZEME]],2,0) | M8: =IF(E10>0,2*(E10-2.4)*E24*0.72/E8/14.50733,0) | N8: =IF(F10>0,2*(F10-2.4)*E24*0.6/E8/14.50733,0) | O8: =IF(G10>0,2*(G10-2.4)*E24*0.5/E8/14.50733,0) | Q8: Botaş Otomatik | S8: =2*E24*(E22-2.4)*0.72/E8/14.50733
B9: Design Basıncı | E9: 0,72 (Hat) | F9: 0,6 (Hat) | G9: 0,5 (Hat) | H9: 0,5 (İst.) | I9: 0,5 (İst.) | J9: 0.72 | M9: =M8*0.75 | N9: =N8*0.75 | O9: =O8*0.75 | Q9: Shell document | S9: *Minimum et kalınlığına göre (Eksi Et kalınlığı Toleransı Dahilinde)
B10: Et Kalınlığı (mm) | E10: =IF(D2="BOTAŞ",VLOOKUP(E8,Tablo244[[ÇAP mm]:[Max Bas. Bar4]],5, 0),VLOOKUP(E8,Tablo2[[ÇAP mm]:[Max Bas. Bar4]],5, 0)) | F10: =IF(D2="BOTAŞ",VLOOKUP(E8,Tablo244[[ÇAP mm]:[Max Bas. Bar4]],7, 0),VLOOKUP(E8,Tablo2[[ÇAP mm]:[Max Bas. Bar4]],7, 0)) | G10: =IF(D2="BOTAŞ",VLOOKUP(E8,Tablo244[[ÇAP mm]:[Max Bas. Bar4]],9, 0),VLOOKUP(E8,Tablo2[[ÇAP mm]:[Max Bas. Bar4]],9, 0)) | H10: =IF(D2="BOTAŞ",VLOOKUP(E8,Tablo244[[ÇAP mm]:[Max Bas. Bar4]],11, 0),VLOOKUP(E8,Tablo2[[ÇAP mm]:[Max Bas. Bar4]],11, 0)) | I10: =IF(D2="BOTAŞ",VLOOKUP(E8,Tablo244[[ÇAP mm]:[Max Bas. Bar5]],13, 0),VLOOKUP(E8,Tablo2[[ÇAP mm]:[Max Bas. Bar5]],13,0)) | J10: 16.66 | M10: =IF(J10>0,2*(J10-2.4)*J24*0.72/J8/14.50733,0) | N10: =IF(J10>0,2*(J10-2.4)*J24*0.6/J8/14.50733,0) | O10: =IF(J10>0,2*(J10-2.4)*10*K24*0.5/J8,0) | Q10: Manuel
B11: Üretim Yöntemi | E11: =IF(E8>323.9,"SAWH",IF(E8>60.3,"ERW HFW","SMLS")) | J11: SAWH
B12: Malzeme Kalitesi | E12: =VLOOKUP(E8,Tablo2[[#All],[ÇAP mm]:[Max Bas. Bar4]],2,0) | J12: X65 | Z12: 0.4
B13: SMYS (Psi) | E13: =VLOOKUP(E12,'Boru Kontrol Tablosu ASME'!D21:N47,2,0) | J13: =VLOOKUP(J12,'Boru SMYS Tablosu'!B5:D16,3,0) | Z13: 0.5
B14: Kimyasal Analiz | E14: C | G14: Max % | H14: =IF(E12='Boru Kontrol Tablosu ASME'!D30,0.18,IF(E12='Boru Kontrol Tablosu ASME'!D31,0.18,IF(E12='Boru Kontrol Tablosu ASME'!D33,0.18,IF(E12='Boru Kontrol Tablosu ASME'!D35,0.18,IF(E12="X56",0.18,IF(E12='Boru Kontrol Tablosu ASME'!D36,0.12,IF(E12='Boru Kontrol Tablosu ASME'!D40,0.12,IF(E12="X70",0.12,IF(E12="X80",0.12,IF(E12="X90",0.1,IF(E12="X100",0.1,IF(E12="X120",0.1,IF(E12="GRADE A",0.22,"hata"))))))))))))) | J14: Max % | K14: =IF(J12='Boru Kontrol Tablosu ASME'!D30,0.18,IF(J12='Boru Kontrol Tablosu ASME'!D31,0.18,IF(J12='Boru Kontrol Tablosu ASME'!D33,0.18,IF(J12='Boru Kontrol Tablosu ASME'!D35,0.18,IF(J12="X56",0.18,IF(J12='Boru Kontrol Tablosu ASME'!D36,0.12,IF(J12='Boru Kontrol Tablosu ASME'!D40,0.12,IF(J12="X70",0.12,IF(J12="X80",0.12,IF(J12="X90",0.1,IF(J12="X100",0.1,IF(J12="X120",0.1,IF(J12="GRADE A",0.22,"hata"))))))))))))) | Z14: 0.6
E15: Mn | G15: Max % | H15: =IF(E12='Boru Kontrol Tablosu ASME'!D30,1.2,IF(E12='Boru Kontrol Tablosu ASME'!D31,1.3,IF(E12='Boru Kontrol Tablosu ASME'!D33,1.3,IF(E12='Boru Kontrol Tablosu ASME'!D35,1.4,IF(E12="X56",1.4,IF(E12='Boru Kontrol Tablosu ASME'!D36,1.6,IF(E12='Boru Kontrol Tablosu ASME'!D40,1.6,IF(E12="X70",1.7,IF(E12="X80",1.85,IF(E12="X90",1.9,IF(E12="X100",1.95,IF(E12="X120",2.0,IF(E12="GRADE A",0.9,"hata"))))))))))))) | J15: Max % | K15: =IF(J12='Boru Kontrol Tablosu ASME'!D30,1.2,IF(J12='Boru Kontrol Tablosu ASME'!D31,1.3,IF(J12='Boru Kontrol Tablosu ASME'!D33,1.3,IF(J12='Boru Kontrol Tablosu ASME'!D35,1.4,IF(J12="X56",1.4,IF(J12='Boru Kontrol Tablosu ASME'!D36,1.6,IF(J12='Boru Kontrol Tablosu ASME'!D40,1.6,IF(J12="X70",1.7,IF(J12="X80",1.85,IF(J12="X90",1.9,IF(J12="X100",1.95,IF(J12="X120",2.0,IF(J12="GRADE A",0.9,"hata"))))))))))))) | Z15: 0.72
E16: P | G16: Max % | H16: 0.025 | J16: Max % | K16: 0.025 | Z16: 0.8
E17: S | G17: Max % | H17: 0.01 | J17: Max % | K17: 0.01
E18: Nb | G18: =IF(H18=0.05,"Max %", "Min%-Max%") | H18: =IF(E12='Boru Kontrol Tablosu ASME'!D30,0.05,IF(E12='Boru Kontrol Tablosu ASME'!D31,0.05,IF(E12='Boru Kontrol Tablosu ASME'!D33,0.05,"0,015-0,050"))) | J18: =IF(K18=0.05,"Max %", "Min%-Max%") | K18: =IF(J12='Boru Kontrol Tablosu ASME'!D30,0.05,IF(J12='Boru Kontrol Tablosu ASME'!D31,0.05,IF(J12='Boru Kontrol Tablosu ASME'!D33,0.05,"0,015-0,050")))
E19: V | G19: Max % | H19: 0.05 | J19: Max % | K19: 0.05
E20: Ti | G20: Max % | H20: 0.04 | J20: Max % | K20: 0.04
E21: N | G21: Max % | H21: 0.009 | J21: Max % | K21: 0.009
B22: Et Kalınlığı Toleransı | D22: Et Kalınlığı Min. (mm) | E22: =IF(E10<8.71,E10-0.04,IF(E10<12.71,E10-0.1,'Boru Seçim-Kontrol Aracı'!E10-0.15)) | F22: =IF(F10<8.71,F10-0.04,IF(F10<12.71,F10-0.1,'Boru Seçim-Kontrol Aracı'!F10-0.15)) | G22: =IF(G10<8.71,G10-0.04,IF(G10<12.71,G10-0.1,'Boru Seçim-Kontrol Aracı'!G10-0.15)) | H22: =IF(H10<8.71,H10-0.04,IF(H10<12.71,H10-0.1,'Boru Seçim-Kontrol Aracı'!H10-0.15)) | I22: =IF(I10<8.71,I10-0.04,IF(I10<12.71,I10-0.1,'Boru Seçim-Kontrol Aracı'!I10-0.15)) | J22: Et Kalınlığı Min. (mm) | K22: =IF(J10<8.71,J10-0.04,IF(J10<12.71,J10-0.1,'Boru Seçim-Kontrol Aracı'!J10-0.15)) | AA22: 35500
D23: Et Kalınlığı Max. (mm) | E23: =IF(E11="SMLS",IF(E10<4.01,E10+0.6,IF('Boru Seçim-Kontrol Aracı'!E10<25,'Boru Seçim-Kontrol Aracı'!E10*1.15,'Boru Seçim-Kontrol Aracı'!E10+3.7)),IF('Boru Seçim-Kontrol Aracı'!E10<5.01,'Boru Seçim-Kontrol Aracı'!E10+0.5,IF('Boru Seçim-Kontrol Aracı'!E10<15,'Boru Seçim-Kontrol Aracı'!E10*1.1,'Boru Seçim-Kontrol Aracı'!E10+1.5))) | F23: =IF(E11="SMLS",IF(F10<4.01,F10+0.6,IF('Boru Seçim-Kontrol Aracı'!F10<25,'Boru Seçim-Kontrol Aracı'!F10*1.15,'Boru Seçim-Kontrol Aracı'!F10+3.7)),IF('Boru Seçim-Kontrol Aracı'!F10<5.01,'Boru Seçim-Kontrol Aracı'!F10+0.5,IF('Boru Seçim-Kontrol Aracı'!F10<15,'Boru Seçim-Kontrol Aracı'!F10*1.1,'Boru Seçim-Kontrol Aracı'!F10+1.5))) | G23: =IF(E11="SMLS",IF(G10<4.01,G10+0.6,IF('Boru Seçim-Kontrol Aracı'!G10<25,'Boru Seçim-Kontrol Aracı'!G10*1.15,'Boru Seçim-Kontrol Aracı'!G10+3.7)),IF('Boru Seçim-Kontrol Aracı'!G10<5.01,'Boru Seçim-Kontrol Aracı'!G10+0.5,IF('Boru Seçim-Kontrol Aracı'!G10<15,'Boru Seçim-Kontrol Aracı'!G10*1.1,'Boru Seçim-Kontrol Aracı'!G10+1.5))) | H23: =IF(E11="SMLS",IF(H10<4.01,H10+0.6,IF('Boru Seçim-Kontrol Aracı'!H10<25,'Boru Seçim-Kontrol Aracı'!H10*1.15,'Boru Seçim-Kontrol Aracı'!H10+3.7)),IF('Boru Seçim-Kontrol Aracı'!H10<5.01,'Boru Seçim-Kontrol Aracı'!H10+0.5,IF('Boru Seçim-Kontrol Aracı'!H10<15,'Boru Seçim-Kontrol Aracı'!H10*1.1,'Boru Seçim-Kontrol Aracı'!H10+1.5))) | I23: =IF(E11="SMLS",IF(I10<4.01,I10+0.6,IF('Boru Seçim-Kontrol Aracı'!I10<25,'Boru Seçim-Kontrol Aracı'!I10*1.15,'Boru Seçim-Kontrol Aracı'!I10+3.7)),IF('Boru Seçim-Kontrol Aracı'!I10<5.01,'Boru Seçim-Kontrol Aracı'!I10+0.5,IF('Boru Seçim-Kontrol Aracı'!I10<15,'Boru Seçim-Kontrol Aracı'!I10*1.1,'Boru Seçim-Kontrol Aracı'!I10+1.5))) | J23: Et Kalınlığı Max. (mm) | K23: =IF(J11="SMLS",IF(J10<4.01,J10+0.6,IF('Boru Seçim-Kontrol Aracı'!J10<25,'Boru Seçim-Kontrol Aracı'!J10*1.15,'Boru Seçim-Kontrol Aracı'!J10+3.7)),IF('Boru Seçim-Kontrol Aracı'!J10<5.01,'Boru Seçim-Kontrol Aracı'!J10+0.5,IF('Boru Seçim-Kontrol Aracı'!J10<15,'Boru Seçim-Kontrol Aracı'!J10*1.1,'Boru Seçim-Kontrol Aracı'!J10+1.5))) | AA23: 42100
B24: Yield Min. (Psi-Mpa) | E24: =VLOOKUP(E12,'Boru SMYS Tablosu'!$B$5:$N$16,3,0) | G24: =VLOOKUP(E12,'Boru SMYS Tablosu'!$B$5:$N$16,7,0) | J24: =VLOOKUP(J12,'Boru SMYS Tablosu'!$B$5:$N$16,3,0) | K24: =VLOOKUP(J12,'Boru SMYS Tablosu'!$B$5:$N$16,7,0) | AA24: 46400
B25: Yield Max. (Psi-Mpa) | E25: =VLOOKUP(E12,'Boru SMYS Tablosu'!$B$5:$N$16,8,0) | G25: =VLOOKUP(E12,'Boru SMYS Tablosu'!$B$5:$N$16,9,0) | J25: =VLOOKUP(J12,'Boru SMYS Tablosu'!$B$5:$N$16,8,0) | K25: =VLOOKUP(J12,'Boru SMYS Tablosu'!$B$5:$N$16,9,0) | Q25: =F10*1.25 | AA25: 52200
B26: Tensile Min (Psi-Mpa) | E26: =VLOOKUP(E13,'Boru SMYS Tablosu'!$D$5:$N$16,8,0) | G26: =VLOOKUP(E13,'Boru SMYS Tablosu'!$D$5:$N$16,9,0) | J26: =VLOOKUP(J13,'Boru SMYS Tablosu'!$D$5:$N$16,8,0) | K26: =VLOOKUP(J13,'Boru SMYS Tablosu'!$D$5:$N$16,9,0) | Q26: =F10*0.75 | AA26: 56600
B27: Tensile Max (Psi-Mpa) | E27: =VLOOKUP(E13,'Boru SMYS Tablosu'!$D$5:$N$16,10,0) | G27: =VLOOKUP(E13,'Boru SMYS Tablosu'!$D$5:$N$16,11,0) | J27: =VLOOKUP(J13,'Boru SMYS Tablosu'!$D$5:$N$16,10,0) | K27: =VLOOKUP(J13,'Boru SMYS Tablosu'!$D$5:$N$16,11,0) | M27: API 5L Test Pressure | N27: API 5L Test Pressure | AA27: 60200
B28: Hydro Test Basıncı Max.(Bar) | E28: =2*E13*E10/E8/14.50733 | F28: =2*E13*F10/E8/14.50733 | G28: =2*E13*G10/E8/14.50733 | H28: =2*E13*H10/E8/14.50733 | I28: =2*E13*I10/E8/14.50733 | J28: =2*J13*J10/J8/14.50733 | M28: =H28*0.9 | N28: =I28*0.9 | AA28: 65300
B29: Hydro Test Basıncı Min.(Bar) | E29: =IF(E28=0,"YOK",E28-2) | F29: =IF(F28=0,"YOK",F28-2) | G29: =IF(G28=0,"YOK",G28-2) | H29: =IF(H28=0,"YOK",H28-2) | I29: =IF(I28=0,"YOK",I28-2) | J29: =J28-2 | AA29: 70300
B30: API 5L Standart Test Pressure (Bar) | E30: =IF(E12="GRADE B",0.6*2*E13*E10/E8/14.50733,IF(E8<219.2,0.75*2*E13*E10/E8/14.50733,IF(E8<508,0.85*2*E13*E10/E8/14.50733,0.9*2*E13*E10/E8/14.50733))) | F30: =IF(E12="GRADE B",0.6*2*E13*F10/E8/14.50733,IF(E8<219.2,0.75*2*E13*F10/E8/14.50733,IF(E8<508,0.85*2*E13*F10/E8/14.50733,0.9*2*E13*F10/E8/14.50733))) | G30: =IF(E12="GRADE B",0.6*2*E13*G10/E8/14.50733,IF(E8<219.2,0.75*2*E13*G10/E8/14.50733,IF(E8<508,0.85*2*E13*G10/E8/14.50733,0.9*2*E13*G10/E8/14.50733))) | H30: =IF(E12="GRADE B",0.6*2*E13*H10/E8/14.50733,IF(E8<219.2,0.75*2*E13*H10/E8/14.50733,IF(E8<508,0.85*2*E13*H10/E8/14.50733,0.9*2*E13*H10/E8/14.50733))) | I30: =IF(E12="GRADE B",0.6*2*E13*I10/E8/14.50733,IF(E8<219.2,0.75*2*E13*I10/E8/14.50733,IF(E8<508,0.85*2*E13*I10/E8/14.50733,0.9*2*E13*I10/E8/14.50733))) | J30: =IF(J12="GRADE B",0.6*2*J13*J10/J8/14.50733,IF(J8<219.2,0.75*2*J13*J10/J8/14.50733,IF(J8<508,0.85*2*J13*J10/J8/14.50733,0.9*2*J13*J10/J8/14.50733)))
B31: API 5L Alternative Test Pressure (Bar)
B32: Boru Çap Toleransları (mm) | E32: Boru Ucu Max. | F32: =IF(D2="BOTAŞ",VLOOKUP(E7,'Boru Kontrol Tablosu BOTAŞ'!B21:T53,16,0),VLOOKUP(E7,'Boru Kontrol Tablosu ASME'!B21:T53,16,0)) | G32: Boru Gövde Max | H32: =IF(D2="BOTAŞ",VLOOKUP(E7,'Boru Kontrol Tablosu BOTAŞ'!B21:T53,18,0),VLOOKUP(E7,'Boru Kontrol Tablosu ASME'!B21:T53,18,0)) | J32: =VLOOKUP(J7,'Boru Kontrol Tablosu ASME'!B21:T53,16,0) | K32: =VLOOKUP(J7,'Boru Kontrol Tablosu ASME'!B21:T53,18,0) | AA32: 80500
E33: Boru Ucu Min. | F33: =IF(D2="BOTAŞ",VLOOKUP(E7,'Boru Kontrol Tablosu BOTAŞ'!B21:T53,17,0),VLOOKUP(E7,'Boru Kontrol Tablosu ASME'!B21:T53,17,0)) | G33: Boru Gövde Min. | H33: =IF(D2="BOTAŞ",VLOOKUP(E7,'Boru Kontrol Tablosu BOTAŞ'!B21:T53,19,0),VLOOKUP(E7,'Boru Kontrol Tablosu ASME'!B21:T53,19,0)) | J33: =VLOOKUP(J7,'Boru Kontrol Tablosu ASME'!B22:T54,17,0) | K33: =VLOOKUP(J7,'Boru Kontrol Tablosu ASME'!B21:T53,19,0) | AA33: 90600
B34: Boru Çevre Toleransı (mm) | E34: Boru Ucu Max. | F34: =F32*3.141592 | G34: Boru Gövde Max | H34: =H32*3.141592 | J34: =J32*3.141592 | K34: =K32*3.141592 | AA34: 100100
E35: Boru Ucu Min. | F35: =F33*3.141592 | G35: Boru Gövde Min. | H35: =H33*3.141592 | J35: =J33*3.141592 | K35: =K33*3.141592 | AA35: 120400
B36: Ovalite (mm) | D36: Boru Ucu | E36: =VLOOKUP(E7,'Boru Kontrol Tablosu ASME'!B21:AI53,25,0) | F36: =VLOOKUP(E7,'Boru Kontrol Tablosu ASME'!B21:AI53,27,0) | G36: =VLOOKUP(E7,'Boru Kontrol Tablosu ASME'!B21:AG53,29,0) | H36: =VLOOKUP(E7,'Boru Kontrol Tablosu ASME'!B21:AG53,31,0) | J36: =IF(J8<60.3,0.45,IF(J8<168.4,IF(J8/J10<75,0.015*J8/2,"Anlaşma"),IF(J8<610.1,0.015*J8/2,IF(J8<1422,IF(J8/J10<75,0.01*J8/2,"Anlaşmaya Bağlı")))))
D37: Boru Gövde | E37: =VLOOKUP(E7,'Boru Kontrol Tablosu ASME'!B21:AI53,26,0) | F37: =VLOOKUP(E7,'Boru Kontrol Tablosu ASME'!B21:AI53,28,0) | G37: =VLOOKUP(E7,'Boru Kontrol Tablosu ASME'!B21:AG53,30,0) | H37: =VLOOKUP(E7,'Boru Kontrol Tablosu ASME'!B21:AG53,32,0) | J37: =IF(J8<60.3,0.6,IF(J8<168.4,IF(J8/J10<75,0.02*J8,"Anlaşmaya Bağlı"),IF(J8<610.1,0.02*J8,IF(J8<1422,IF(J8/J10<75,0.015*J8,"Anlaşmaya Bağlı")))))
B38: Minimum Uzama (mm) | D38: Malzeme (mm) | E38: =VLOOKUP(E7,'Boru Kontrol Tablosu ASME'!B21:AQ53,36,0) | F38: =VLOOKUP(E7,'Boru Kontrol Tablosu ASME'!B21:AQ53,38,0) | G38: =VLOOKUP(E7,'Boru Kontrol Tablosu ASME'!B21:AQ53,40,0) | H38: =VLOOKUP(E7,'Boru Kontrol Tablosu ASME'!B21:AR53,42,0) | I38: =VLOOKUP(E7,'Boru Kontrol Tablosu ASME'!B21:AS53,44,0) | J38: =1940*(POWER(IF(J10*38<485,ROUND(J10*38,-1),485),0.2))/POWER(K26,0.9)
D39: Kaynak | E39: 10 | F39: 10 | G39: 10 | H39: 10 | I39: 10 | J39: 10
B40: Radial Offset Max. (mm) | E40: =IF(E11="SAWH",IF(E10<15.01,1.5*0.75,IF(E10<25.01,0.1*0.75*E10,IF(E10>25.01,2.5*0.75,"HATA"))),"Değer Yok") | F40: =IF(E11="SAWH",IF(F10<15.01,1.5*0.75,IF(F10<25.01,0.1*0.75*F10,IF(F10>25.01,2.5*0.75,"HATA"))),"Değer Yok") | G40: =IF(E11="SAWH",IF(G10<15.01,1.5*0.75,IF(G10<25.01,0.1*0.75*G10,IF(G10>25.01,2.5*0.75,"HATA"))),"Değer Yok") | H40: =IF(E11="SAWH",IF(H10<15.01,1.5*0.75,IF(H10<25.01,0.1*0.75*H10,IF(H10>25.01,2.5*0.75,"HATA"))),"Değer Yok") | I40: =IF(E11="SAWH",IF(I10<15.01,1.5*0.75,IF(I10<25.01,0.1*0.75*I10,IF(I10>25.01,2.5*0.75,"HATA"))),"Değer Yok") | J40: =IF(J11="SAWH",IF(J10<15.01,1.5*0.75,IF(J10<25.01,0.1*0.75*J10,IF(J10>25.01,2.5*0.75,"HATA"))),"Değer Yok")
...

Sheet Boru SMYS Tablosu
B2: Pipe
B3: API 5L | C3: ISO 3183 | D3: SMYS(psi) | E3: Yield/Tensile | F3: Çentik Darbe Malzeme | G3: Çentik Darbe Kaynak | H3: Yield min MPa | I3: Yield max psi | J3: Yield max Mpa | K3: Tensile Min.Psi | L3: Tensile Min.Mpa | M3: Tensile Max.Psi | N3: Tensile Max.Mpa | O3: Strain Value
B4: GRADE A | C4: L210 | D4: 30500 | H4: 210
B5: GRADE B | C5: L245 | D5: 35500 | E5: 0.8 | F5: 27 | G5: 27 | H5: 245 | I5: 65300 | J5: 450 | K5: 60200 | L5: 415 | M5: 95000 | N5: 655 | O5: 0.1375
B6: X42 | C6: L290 | D6: 42100 | E6: 0.85 | F6: 27 | G6: 27 | H6: 290 | I6: 71800 | J6: 495 | K6: 60200 | L6: 415 | M6: 95000 | N6: 655 | O6: 0.1375
B7: X46 | C7: L320 | D7: 46400 | E7: 0.85 | F7: 48 | G7: 36 | H7: 320 | I7: 76100 | J7: 525 | K7: 63100 | L7: 435 | M7: 95000 | N7: 655 | O7: 0.1325
B8: X52 | C8: L360 | D8: 52200 | E8: 0.87 | F8: 48 | G8: 36 | H8: 360 | I8: 76900 | J8: 530 | K8: 66700 | L8: 460 | M8: 110200 | N8: 760 | O8: 0.125
B9: X56 | C9: L390 | D9: 56600 | E9: 0.87 | F9: 48 | G9: 36 | H9: 390 | I9: 79000 | J9: 545 | K9: 71100 | L9: 490 | M9: 110200 | N9: 760 | O9: 0.1175
B10: X60 | C10: L415 | D10: 60200 | E10: 0.9 | F10: 60 | G10: 45 | H10: 415 | I10: 81900 | J10: 565 | K10: 75400 | L10: 520 | M10: 110200 | N10: 760 | O10: 0.1125
B11: X65 | C11: L450 | D11: 65300 | E11: 0.9 | F11: 60 | G11: 45 | H11: 450 | I11: 87000 | J11: 600 | K11: 77600 | L11: 535 | M11: 110200 | N11: 760 | O11: 0.11
B12: X70 | C12: L485 | D12: 70300 | E12: 0.93 | F12: 60 | G12: 45 | H12: 485 | I12: 92100 | J12: 635 | K12: 82700 | L12: 570 | M12: 110200 | N12: 760 | O12: 0.1025
B13: X80 | C13: L555 | D13: 80500 | E13: 0.93 | F13: 90 | G13: 68 | H13: 555 | I13: 102300 | J13: 705 | K13: 90600 | L13: 625 | M13: 119700 | N13: 825 | O13: 0.095
B14: X90 | C14: L625 | D14: 90600 | E14: 0.95 | H14: 625 | I14: 112400 | J14: 775 | K14: 100800 | L14: 695 | M14: 132700 | N14: 915 | O14: 0.085
B15: X100 | C15: L690 | D15: 100100 | E15: 0.97 | H15: 690 | I15: 121800 | J15: 840 | K15: 110200 | L15: 760 | M15: 143600 | N15: 990 | O15: 0.08
B16: X120 | C16: L830 | D16: 120400 | E16: 0.99 | H16: 830 | I16: 152300 | J16: 1050 | K16: 132700 | L16: 915 | M16: 166100 | N16: 1145 | O16: 0.0675

Sheet Reinforcement Pad
A1: Branch reinforcement calculations as per ASME B 31.3 1996 Edition: | F1: (for nomenclature refer ASME 31.3 1996 Edition)
F2: Nom. run size (inch) | I2: 48"
A3: Enter the following data in the units indicated | F3: Nom. branch size (inch) | I3: 4"
A4: 1 . | B4: Dh=O.D of header or run pipe in mm | E4: =VLOOKUP(I2,Tablo2[[ÇAP inch]:[ÇAP mm]],2,0)
B5: Db=O.D. of branch pipe in mm | E5: =VLOOKUP(I3,Tablo2[[ÇAP inch]:[ÇAP mm]],2,0)
A6: 2 . | B6: Nominal thickness of branch pipe in mm.Tb | E6: =VLOOKUP(I3,Tablo2[[ÇAP inch]:[Et Kalınlığı 5]],12,0)
B7: Corrosion allowance for branch pipe in mm. Cb | E7: 1.5
A8: 3 | B8: Nominal thickness of run pipe in mm Th | E8: =VLOOKUP(I2,Tablo2[[ÇAP inch]:[Et Kalınlığı 5]],12,0)
B9: Corrosion allowance for run pipe in mm. Ch | E9: 1.5
A10: 4 | B10: Internal design gauge pressure (bar) | E10: 82.5
A11: 5 | B11: Basic allowable stress for material of run pipe,(table A-1) psi(g), Sh | E11: =VLOOKUP(I2,Tablo2[],4,0)
A12: 6 | B12: Basic allowable stress for material of branch pipe,(Table A-1) psi(g) Sb | E12: =VLOOKUP(I3,Tablo2[],4,0) | J12: =IF(E8<8.71,E8-0.04,IF(E8<12.71,E8-0.1,E8-0.15))
A13: 7 | B13: Quality factor from (Table A-1B), for run pipe.Ejh | E13: 1 | F13: d1 effective length removed from pipe at branch mm | J13: =(E5-2*((1-E16/100)*E6) +2*E7)/SIN(PI()*E21/180)
A14: 8 | B14: Quality factor from (Table A-1B),for branch pipe.Ejb | E14: 1 | F14: th pressure design thickness for the run pipe mm | J14: =(E10*E4)/(2*(E11*E13+0.4*E10))
A15: 9 | B15: Negative mill tolerance for run pipe in % . Nh | E15: 12.5 | F15: tb pressure design thickness for the branch pipe mm | J15: =(E10*E5)/(2*(E12*E14+0.4*E10)) | S15: 0.5
A16: 10 | B16: Negative mill tolerance for branch pipe in % . Nb | E16: 12.5 | F16: (Tb-Cb)+(Th-Ch)+d1/2 mm | J16: =(E6*(1-E16/100)-E7)+(E8*(1-E15/100)-E9)+J13/2 | S16: 0.6
A17: * | B17: Do you want to check the connection | E17: YES | F17: Greater of d1 and (Tb-Cb)+(Th-Ch)+d1/2 | J17: =IF(J13>=J16,J13,J16) | S17: 0.72
B18: with reinforcing ring.specify YES / NO | F18: d2 half width of reinforcement zone mm | J18: =IF(J17<=E4,J17,E4) | S18: 0.8
A19: PLEASE NOTE SET Tr = 0 FOR CHECKING IF REINFORCEMENT PAD IS REQUIRED | F19: A2 area from excess thickness in the run pipe mm2 | J19: =(2*J18-J13)*(E8*(1-E15/100)-J14-E9)
A20: 11 | B20: Tr minimum thickness of reinforcing ring or saddle mm | E20: 0
A21: 12 | B21: b smaller angle between axes of branch and run in degree | E21: 90 | F21: 2.5(Th-Ch) mm | J21: =2.5*(E8*(1-E15/100)-E9)
F22: 2.5(Tb-Cb)+Tr mm | J22: =2.5*(E6*(1-E16/100)-E7) +E20
F23: L4, Lesser of 2.5(Th-Ch)and 2.5(Tb-Cb)+Tr mm | J23: =IF(J21<=J22,J21,J22) | K23: Height of reinforcement zone outside of run pipe | O23: Sütun1 | P23: D (Inch) | Q23: D (mm) | R23: S (Mpa) | S23: P (Bar)
A24: 13 | B24: Length of reinforcing pad measured along the run mm . Lr | E24: =IF(E17="YES",(2*J18-1),0) | O24: Nom. run size | P24: 18" | Q24: =VLOOKUP(P24,Tablo2[[ÇAP inch]:[ÇAP mm]],2,0) | R24: =ROUND(VLOOKUP(P24,Tablo2[[ÇAP inch]:[Tensile Mpa]],4,0)/145.0377,0) | S24: 75
B25: =IF(E24=2*J18-1," MAXIMUM LENGTH OF SADDLE IN COMPLAINCE WITH CODE"," ") | F25: A3 area from excess thickness in branch pipe mm2 | J25: =2*J23*((E6*(1-E16/100)-E7-J15)/(SIN(PI()*E21/180))) | O25: Nom. branch size | P25: 4" | Q25: =VLOOKUP(P25,Tablo2[[ÇAP inch]:[ÇAP mm]],2,0) | R25: =ROUND(VLOOKUP(P25,Tablo2[[ÇAP inch]:[Tensile Mpa]],4,0)/145.0377,0) | S25: 75
F26: Less of L4 &Tr forcalculating reinforcement area in ring | J26: =IF(E20<=J23,E20,J23) | O26: Selected Reinforcing Material | R26: 355
H27: PLEASE NOTE THIS SHOULD NOT BE LESS THAN Db | O27: Run Pipe Design Factor | Q27: 0.5
A28: PLEASE NOTE SET Ta = 0 FOR CHECKING IF REINFORCEMENT PAD IS REQUIRED | F28: Thickness used in ring area calculation | J28: =IF(E20=0,0,J26) | O28: İstasyon İçi Borulama
A29: 14 | B29: Enter next higher,available thk ta of reinforcing ring in mm. | E29: 0 | F29: Reinforcement area in reinforcing ring mm2 | J29: =J28*(E24-E5/SIN(E21*(PI()/180))) | O29: B | P29: =IF(S25<82.5, VLOOKUP(P25,Tablo244[[ÇAP inch]:[Et Kalınlığı 5]],12,0),VLOOKUP(P25,Tablo244[[ÇAP inch]:[Et Kalınlığı 5]],14,0)) | Q29: mm | S29: =IF(P29>2*P11,"Değer 2*d den büyük!","Değer uygun")
A30: 15 | B30: Length of reinforcement pad for ta in mm. | D30: =IF( J29=0,"NOT APPLICABLE",ROUND(((J29/E29)+(E5/SIN(E21*(PI()/180)))), 0)) | F30: Throat dimension of fillet weld mm tc | J30: =IF(0.7*E6<=6,0.7*E6,6) | O30: Cb | P30: 0 | Q30: mm | R30: Corrosion allowance for branch pipe in mm. | S30: =IF(P30>2*P12,"Değer 2*d den büyük!","Değer uygun")
B31: =IF(D30="NOT APPLICABLE"," ",(IF(D30>2*J18,"TRY WITH NEXT HIGHER THK REINFORCING RING ( Please note,this length shall be less than twice half width of reinforcement zone ) ",IF(D30<=E5+100,"TRY WITH NEXT LOWER THK REINFORCING RING ( Please note,this length shall be greater than (O.D of branch pipe + 100 )mm;also refer RESULT 3 , a possible solution with available thickness )","LENGTH OF SADDLE IS IN COMPLAINCE WITH CODE")))) | F31: Weld reinforcement area without ring mm2 | J31: =(J30/0.707)^2 | O31: d | P31: =Q25-2*P29 | Q31: mm | S31: =IF(P31>2*P13,"Değer 2*d den büyük!","Değer uygun")
F32: Leg dimension of weld at reinforcement ring mm | J32: =0.5*E20/0.707 | O32: H | P32: =IF(S24<82.5,IF(Q27=0.5,VLOOKUP(P24,Tablo244[],10,0),IF(Q27=0.6,VLOOKUP(P24,'Boru Kontrol Tablosu BOTAŞ'!B21:R53,8,0),IF(Q27=0.72,VLOOKUP(P24,Tablo244[],6,0),"Uygun Dizayn Değeri Seçin"))),"İstasyon Borusu mu") | Q32: mm | S32: =IF(P32>2*P14,"Değer 2*d den büyük!","Değer uygun")
F33: Weld dim. at ring used in calculation mm | J33: =IF(J32<=J23,J32,J23) | O33: M | P33: 11 | Q33: mm | R33: (Selected Wall Thick.) | S33: =IF(P33>2*P15,"Değer 2*d den büyük!","Değer uygun")
F34: Weld reinforcement area at ring mm2 | J34: =J33*J32 | O34: t | P34: =S24/10*Q24/2/R24/0.5 | Q34: mm | S34: =IF(P34>2*P16,"Değer 2*d den büyük!","Değer uygun")
A35: Result | B35: =IF((INT(J36)-INT(J37))>=0,"1. Branch connection is OK","1. Area available not sufficient pl try with reinforcement , increase saddle thk and/or saddle length.") | O35: Ch | P35: 0 | Q35: mm | R35: Corrosion allowance for run pipe in mm. | S35: =IF(P35>2*P17,"Değer 2*d den büyük!","Değer uygun")
B36: =IF(AND(J36>J37,E20=0),"2. Reinforcement not required","2. Reinforcement is required " ) | F36: Total area available for reinforcement mm2 | J36: =IF(J23>=E20,J34+J31+J29+J25+J19,J19+J25+J29+J34) | O36: tb | P36: =S25*Q25/2/R25/0.5/10 | Q36: mm | S36: =IF(P36>2*P18,"Değer 2*d den büyük!","Değer uygun")
B37: =IF(E29=0," ",IF(AND(J36>J37,E20=0)," ", "3. Size of reinforcing ring, width(mm) x thk(mm)")) | C37: =IF(E29=0," ",IF(AND(J36>J37,E20=0)," ",ROUND(((IF(D30<=E5+100,ROUND((E5+100),0),ROUND(D30,0)))-E5)/2,0))) | D37: =IF(E29=0," ",IF(AND(J36>J37,E20=0)," ", " X ")) | E37: =IF(E29=0," ",IF(AND(J36>J37,E20=0)," ",E29)) | F37: Area required mm2 | J37: =J14*J13*(2-SIN(E21*PI()/180)) | O37: L1 | P37: =2.5*P32 | Q37: mm | S37: =IF(P37>2*P19,"Değer 2*d den büyük!","Değer uygun") | AA37: =914.1-882.1
O38: L2 | P38: =2.5*P29+P33 | Q38: mm | S38: =IF(P38>2*P20,"Değer 2*d den büyük!","Değer uygun") | AA38: =13428.5/882.1
C39: PPD. BY : | F39: JOB NO. | K39: DWG.NO. | M39: ISSUE | O39: L | P39: =IF(P37<P38,P37,P38) | Q39: mm | S39: =IF(P39>2*P21,"Değer 2*d den büyük!","Değer uygun")
C40: CKD. BY : | M40: R0 | O40: Ar | P40: =P31*P34 | Q40: mm2 | S40: =IF(P40>2*P22,"Değer 2*d den büyük!","Değer uygun")
...

Sheet Boru Kontrol Tablosu BOTAŞ
B2: ERW HFW
B3: SAWH
B4: SAWL
B5: COW
B6: SEAMLESS
B11: =VLOOKUP('Et Kalınlığı Hesaplama'!E5,Tablo244[ÇAP mm],6,FALSE)
G16: Design Pressure 75 | O16: Design Pressure 82,5 | Z16: Ovalite mm | AJ16: Minimun Elongation
G17: Boru Hattı | M17: İstayon | O17: İstayon | Q17: Boru Çap Toleransları mm | U17: Boru Hattı | X17: İstayon | Z17: Boru Hattı | AF17: İstayon | AJ17: Boru Hattı | AP17: İstayon
G18: F=0,72 | I18: F=0,60 | K18: F=0,50 | M18: F=0,50 | O18: F=0,50 | U18: F=0,72 | V18: F=0,6 | W18: F=0,5 | X18: F=0,5 | Y18: F=0,5 | Z18: F=0,72 | AB18: F=0,6 | AD18: F=0,5 | AF18: F=0,5 | AH18: F=0,5 | AJ18: F=0,72 | AL18: F=0,6 | AN18: F=0,5 | AP18: F=0,5 | AR18: F=0,5 (82,5)
B19: 1 | C19: 2 | D19: 3 | E19: 4 | F19: 5 | G19: 6 | H19: 7 | I19: 8 | J19: 9 | K19: 10 | L19: 11 | M19: 12 | N19: 13 | O19: 14 | P19: 15 | Q19: 16 | R19: 17 | S19: 18 | T19: 19 | U19: 20 | V19: 21 | W19: 22 | X19: 23 | Y19: 24 | Z19: 25 | AA19: 26 | AB19: 27 | AC19: 28 | AD19: 29 | AE19: 30 | AF19: 31 | AG19: 32 | AH19: 33 | AI19: 34 | AJ19: 35 | AK19: 36 | AL19: 37 | AM19: 38 | AN19: 39 | AO19: 40 | AP19: 41 | AQ19: 42 | AR19: 43 | AS19: 44
B20: ÇAP inch | C20: ÇAP mm | D20: MALZEME | E20: SMYS Psi | F20: Tensile Mpa | G20: Et Kalınlığı | H20: Max Bas. bar | I20: Et Kalınlığı 2 | J20: Max Bas. Bar2 | K20: Et Kalınlığı 3 | L20: Max Bas. Bar3 | M20: Et Kalınlığı 4 | N20: Max Bas. Bar4 | O20: Et Kalınlığı 5 | P20: Max Bas. Bar5 | Q20: Boru Ucu MAX | R20: Boru Ucu Min | S20: Boru Gövde MAX | T20: Boru Gövde Min | U20: D/t | V20: D/t2 | W20: D/t3 | X20: D/t4 | Y20: D/t5 | Z20: Boru Ucu 1 | AA20: Boru Gövdesi 1 | AB20: Boru Ucu 2 | AC20: Boru Gövdesi 2 | AD20: Boru Ucu 3 | AE20: Boru Gövdesi 3 | AF20: Boru Ucu 4 | AG20: Boru Gövdesi 4 | AH20: Boru Ucu 5 | AI20: Boru Gövdesi 5 | AJ20: Axc mm2 | AK20: Af mm | AL20: Axc mm22 | AM20: Af mm2 | AN20: Axc mm23 | AO20: Af mm3 | AP20: Axc mm24 | AQ20: Af mm4 | AR20: Axc mm25 | AS20: Af mm5
B21: ½" | C21: 21.3 | D21: GRADE B | E21: 35500 | F21: 415 | M21: 3.7 | N21: =2*Tablo244[[#This Row],[SMYS Psi]]*Tablo244[[#This Row],[Et Kalınlığı 4]]/Tablo244[[#This Row],[ÇAP mm]]/14.50377 | O21: 3.7 | P21: =2*Tablo244[[#This Row],[SMYS Psi]]*Tablo244[[#This Row],[Et Kalınlığı 5]]/Tablo244[[#This Row],[ÇAP mm]]/14.50377 | Q21: =Tablo244[[#This Row],[ÇAP mm]]+0.4 | R21: =Tablo244[[#This Row],[ÇAP mm]]-0.8 | S21: =Tablo244[[#This Row],[ÇAP mm]]+0.4 | T21: =Tablo244[[#This Row],[ÇAP mm]]-0.8 | X21: =Tablo244[[#This Row],[ÇAP mm]]/Tablo244[[#This Row],[Et Kalınlığı 4]] | Y21: =Tablo244[[#This Row],[ÇAP mm]]/Tablo244[[#This Row],[Et Kalınlığı 5]] | AF21: =0.9/2 | AG21: =1.2 | AH21: =0.9/2 | AI21: 1.2 | AP21: =IF(40*Tablo244[[#This Row],[Et Kalınlığı 4]]<485,Tablo244[[#This Row],[Et Kalınlığı 4]]*40,485) | AQ21: =1940*POWER(ROUND(Tablo151[[#This Row],[Axc mm24]],-1),0.2)/POWER(Tablo244[[#This Row],[Tensile Mpa]],0.9) | AR21: =IF(40*Tablo244[[#This Row],[Et Kalınlığı 5]]<485,Tablo244[[#This Row],[Et Kalınlığı 4]]*40,485) | AS21: =1940*POWER(ROUND(Tablo151[[#This Row],[Axc mm25]],-1),0.2)/POWER(Tablo244[[#This Row],[Tensile Mpa]],0.9)
B22: ¾" | C22: 26.7 | D22: GRADE B | E22: 35500 | F22: 415 | M22: 3.9 | N22: =2*Tablo244[[#This Row],[SMYS Psi]]*Tablo244[[#This Row],[Et Kalınlığı 4]]/Tablo244[[#This Row],[ÇAP mm]]/14.50377 | O22: 3.9 | P22: =2*Tablo244[[#This Row],[SMYS Psi]]*Tablo244[[#This Row],[Et Kalınlığı 5]]/Tablo244[[#This Row],[ÇAP mm]]/14.50377 | Q22: =Tablo244[[#This Row],[ÇAP mm]]+0.4 | R22: =Tablo244[[#This Row],[ÇAP mm]]-0.8 | S22: =Tablo244[[#This Row],[ÇAP mm]]+0.4 | T22: =Tablo244[[#This Row],[ÇAP mm]]-0.8 | X22: =Tablo244[[#This Row],[ÇAP mm]]/Tablo244[[#This Row],[Et Kalınlığı 4]] | Y22: =Tablo244[[#This Row],[ÇAP mm]]/Tablo244[[#This Row],[Et Kalınlığı 5]] | AF22: =0.9/2 | AG22: =1.2 | AH22: =0.9/2 | AI22: 1.2 | AP22: =IF(40*Tablo244[[#This Row],[Et Kalınlığı 4]]<485,Tablo244[[#This Row],[Et Kalınlığı 4]]*40,485) | AQ22: =1940*POWER(ROUND(Tablo151[[#This Row],[Axc mm24]],-1),0.2)/POWER(Tablo244[[#This Row],[Tensile Mpa]],0.9) | AR22: =IF(40*Tablo244[[#This Row],[Et Kalınlığı 5]]<485,Tablo244[[#This Row],[Et Kalınlığı 4]]*40,485) | AS22: =1940*POWER(ROUND(Tablo151[[#This Row],[Axc mm25]],-1),0.2)/POWER(Tablo244[[#This Row],[Tensile Mpa]],0.9)
B23: 1" | C23: 33.4 | D23: GRADE B | E23: 35500 | F23: 415 | M23: 4.6 | N23: =2*Tablo244[[#This Row],[SMYS Psi]]*Tablo244[[#This Row],[Et Kalınlığı 4]]/Tablo244[[#This Row],[ÇAP mm]]/14.50377 | O23: 4.6 | P23: =2*Tablo244[[#This Row],[SMYS Psi]]*Tablo244[[#This Row],[Et Kalınlığı 5]]/Tablo244[[#This Row],[ÇAP mm]]/14.50377 | Q23: =Tablo244[[#This Row],[ÇAP mm]]+0.4 | R23: =Tablo244[[#This Row],[ÇAP mm]]-0.8 | S23: =Tablo244[[#This Row],[ÇAP mm]]+0.4 | T23: =Tablo244[[#This Row],[ÇAP mm]]-0.8 | X23: =Tablo244[[#This Row],[ÇAP mm]]/Tablo244[[#This Row],[Et Kalınlığı 4]] | Y23: =Tablo244[[#This Row],[ÇAP mm]]/Tablo244[[#This Row],[Et Kalınlığı 5]] | AF23: =0.9/2 | AG23: =1.2 | AH23: =0.9/2 | AI23: 1.2 | AP23: =IF(40*Tablo244[[#This Row],[Et Kalınlığı 4]]<485,Tablo244[[#This Row],[Et Kalınlığı 4]]*40,485) | AQ23: =1940*POWER(ROUND(Tablo151[[#This Row],[Axc mm24]],-1),0.2)/POWER(Tablo244[[#This Row],[Tensile Mpa]],0.9) | AR23: =IF(40*Tablo244[[#This Row],[Et Kalınlığı 5]]<485,Tablo244[[#This Row],[Et Kalınlığı 4]]*40,485) | AS23: =1940*POWER(ROUND(Tablo151[[#This Row],[Axc mm25]],-1),0.2)/POWER(Tablo244[[#This Row],[Tensile Mpa]],0.9)
B24: 1¼" | C24: 42.2 | D24: GRADE B | E24: 35500 | F24: 415 | M24: 4.9 | N24: =2*Tablo244[[#This Row],[SMYS Psi]]*Tablo244[[#This Row],[Et Kalınlığı 4]]/Tablo244[[#This Row],[ÇAP mm]]/14.50377 | O24: 4.9 | P24: =2*Tablo244[[#This Row],[SMYS Psi]]*Tablo244[[#This Row],[Et Kalınlığı 5]]/Tablo244[[#This Row],[ÇAP mm]]/14.50377 | Q24: =Tablo244[[#This Row],[ÇAP mm]]+0.4 | R24: =Tablo244[[#This Row],[ÇAP mm]]-0.8 | S24: =Tablo244[[#This Row],[ÇAP mm]]+0.4 | T24: =Tablo244[[#This Row],[ÇAP mm]]-0.8 | X24: =Tablo244[[#This Row],[ÇAP mm]]/Tablo244[[#This Row],[Et Kalınlığı 4]] | Y24: =Tablo244[[#This Row],[ÇAP mm]]/Tablo244[[#This Row],[Et Kalınlığı 5]] | AF24: =0.9/2 | AG24: =1.2 | AH24: =0.9/2 | AI24: 1.2 | AP24: =IF(40*Tablo244[[#This Row],[Et Kalınlığı 4]]<485,Tablo244[[#This Row],[Et Kalınlığı 4]]*40,485) | AQ24: =1940*POWER(ROUND(Tablo151[[#This Row],[Axc mm24]],-1),0.2)/POWER(Tablo244[[#This Row],[Tensile Mpa]],0.9) | AR24: =IF(40*Tablo244[[#This Row],[Et Kalınlığı 5]]<485,Tablo244[[#This Row],[Et Kalınlığı 4]]*40,485) | AS24: =1940*POWER(ROUND(Tablo151[[#This Row],[Axc mm25]],-1),0.2)/POWER(Tablo244[[#This Row],[Tensile Mpa]],0.9)
B25: 1½" | C25: 48.3 | D25: GRADE B | E25: 35500 | F25: 415 | M25: 5.1 | N25: =2*Tablo244[[#This Row],[SMYS Psi]]*Tablo244[[#This Row],[Et Kalınlığı 4]]/Tablo244[[#This Row],[ÇAP mm]]/14.50377 | O25: 5.1 | P25: =2*Tablo244[[#This Row],[SMYS Psi]]*Tablo244[[#This Row],[Et Kalınlığı 5]]/Tablo244[[#This Row],[ÇAP mm]]/14.50377 | Q25: =Tablo244[[#This Row],[ÇAP mm]]+0.4 | R25: =Tablo244[[#This Row],[ÇAP mm]]-0.8 | S25: =Tablo244[[#This Row],[ÇAP mm]]+0.4 | T25: =Tablo244[[#This Row],[ÇAP mm]]-0.8 | X25: =Tablo244[[#This Row],[ÇAP mm]]/Tablo244[[#This Row],[Et Kalınlığı 4]] | Y25: =Tablo244[[#This Row],[ÇAP mm]]/Tablo244[[#This Row],[Et Kalınlığı 5]] | AF25: =0.9/2 | AG25: =1.2 | AH25: =0.9/2 | AI25: 1.2 | AP25: =IF(40*Tablo244[[#This Row],[Et Kalınlığı 4]]<485,Tablo244[[#This Row],[Et Kalınlığı 4]]*40,485) | AQ25: =1940*POWER(ROUND(Tablo151[[#This Row],[Axc mm24]],-1),0.2)/POWER(Tablo244[[#This Row],[Tensile Mpa]],0.9) | AR25: =IF(40*Tablo244[[#This Row],[Et Kalınlığı 5]]<485,Tablo244[[#This Row],[Et Kalınlığı 4]]*40,485) | AS25: =1940*POWER(ROUND(Tablo151[[#This Row],[Axc mm25]],-1),0.2)/POWER(Tablo244[[#This Row],[Tensile Mpa]],0.9)
B26: 2" | C26: 60.3 | D26: GRADE B | E26: 35500 | F26: 415 | M26: 5.5 | N26: =2*Tablo244[[#This Row],[SMYS Psi]]*Tablo244[[#This Row],[Et Kalınlığı 4]]/Tablo244[[#This Row],[ÇAP mm]]/14.50377 | O26: 5.5 | P26: =2*Tablo244[[#This Row],[SMYS Psi]]*Tablo244[[#This Row],[Et Kalınlığı 5]]/Tablo244[[#This Row],[ÇAP mm]]/14.50377 | Q26: =Tablo244[[#This Row],[ÇAP mm]]+1.6 | R26: =Tablo244[[#This Row],[ÇAP mm]]-0.4 | S26: =Tablo244[[#This Row],[ÇAP mm]]*1.0075 | T26: =Tablo244[[#This Row],[ÇAP mm]]*0.9925 | X26: =Tablo244[[#This Row],[ÇAP mm]]/Tablo244[[#This Row],[Et Kalınlığı 4]] | Y26: =Tablo244[[#This Row],[ÇAP mm]]/Tablo244[[#This Row],[Et Kalınlığı 5]] | AF26: =IF(Tablo244[[#This Row],[ÇAP mm]]/Tablo244[[#This Row],[Et Kalınlığı 4]]<75,Tablo244[[#This Row],[ÇAP mm]]*0.015/2,"Anlaşmaya bağlıdır.") | AG26: =IF(Tablo244[[#This Row],[ÇAP mm]]/Tablo244[[#This Row],[Et Kalınlığı 4]]<75,Tablo244[[#This Row],[ÇAP mm]]*0.02,"Anlaşmaya bağlıdır.") | AH26: =IF(Tablo244[[#This Row],[ÇAP mm]]/Tablo244[[#This Row],[Et Kalınlığı 4]]<75,Tablo244[[#This Row],[ÇAP mm]]*0.015/2,"Anlaşmaya bağlıdır.") | AI26: =IF(Tablo244[[#This Row],[ÇAP mm]]/Tablo244[[#This Row],[Et Kalınlığı 5]]<75,Tablo244[[#This Row],[ÇAP mm]]*0.02,"Anlaşmaya bağlıdır.") | AP26: =IF(40*Tablo244[[#This Row],[Et Kalınlığı 4]]<485,Tablo244[[#This Row],[Et Kalınlığı 4]]*40,485) | AQ26: =1940*POWER(ROUND(Tablo151[[#This Row],[Axc mm24]],-1),0.2)/POWER(Tablo244[[#This Row],[Tensile Mpa]],0.9) | AR26: =IF(40*Tablo244[[#This Row],[Et Kalınlığı 5]]<485,Tablo244[[#This Row],[Et Kalınlığı 4]]*40,485) | AS26: =1940*POWER(ROUND(Tablo151[[#This Row],[Axc mm25]],-1),0.2)/POWER(Tablo244[[#This Row],[Tensile Mpa]],0.9)
B27: 2½" | C27: 73 | D27: GRADE B | E27: 35500 | F27: 415 | M27: 5.2 | N27: =2*Tablo244[[#This Row],[SMYS Psi]]*Tablo244[[#This Row],[Et Kalınlığı 4]]/Tablo244[[#This Row],[ÇAP mm]]/14.50377 | O27: 5.2 | P27: =2*Tablo244[[#This Row],[SMYS Psi]]*Tablo244[[#This Row],[Et Kalınlığı 5]]/Tablo244[[#This Row],[ÇAP mm]]/14.50377 | Q27: =Tablo244[[#This Row],[ÇAP mm]]+1.6 | R27: =Tablo244[[#This Row],[ÇAP mm]]-0.4 | S27: =Tablo244[[#This Row],[ÇAP mm]]*1.0075 | T27: =Tablo244[[#This Row],[ÇAP mm]]*0.9925 | X27: =Tablo244[[#This Row],[ÇAP mm]]/Tablo244[[#This Row],[Et Kalınlığı 4]] | Y27: =Tablo244[[#This Row],[ÇAP mm]]/Tablo244[[#This Row],[Et Kalınlığı 5]] | AF27: =IF(Tablo244[[#This Row],[ÇAP mm]]/Tablo244[[#This Row],[Et Kalınlığı 4]]<75,Tablo244[[#This Row],[ÇAP mm]]*0.015/2,"Anlaşmaya bağlıdır.") | AG27: =IF(Tablo244[[#This Row],[ÇAP mm]]/Tablo244[[#This Row],[Et Kalınlığı 4]]<75,Tablo244[[#This Row],[ÇAP mm]]*0.02,"Anlaşmaya bağlıdır.") | AH27: =IF(Tablo244[[#This Row],[ÇAP mm]]/Tablo244[[#This Row],[Et Kalınlığı 4]]<75,Tablo244[[#This Row],[ÇAP mm]]*0.015/2,"Anlaşmaya bağlıdır.") | AI27: =IF(Tablo244[[#This Row],[ÇAP mm]]/Tablo244[[#This Row],[Et Kalınlığı 5]]<75,Tablo244[[#This Row],[ÇAP mm]]*0.02,"Anlaşmaya bağlıdır.") | AP27: =IF(40*Tablo244[[#This Row],[Et Kalınlığı 4]]<485,Tablo244[[#This Row],[Et Kalınlığı 4]]*40,485) | AQ27: =1940*POWER(ROUND(Tablo151[[#This Row],[Axc mm24]],-1),0.2)/POWER(Tablo244[[#This Row],[Tensile Mpa]],0.9) | AR27: =IF(40*Tablo244[[#This Row],[Et Kalınlığı 5]]<485,Tablo244[[#This Row],[Et Kalınlığı 4]]*40,485) | AS27: =1940*POWER(ROUND(Tablo151[[#This Row],[Axc mm25]],-1),0.2)/POWER(Tablo244[[#This Row],[Tensile Mpa]],0.9)
B28: 3" | C28: 88.9 | D28: GRADE B | E28: 35500 | F28: 415 | M28: 5.5 | N28: =2*Tablo244[[#This Row],[SMYS Psi]]*Tablo244[[#This Row],[Et Kalınlığı 4]]/Tablo244[[#This Row],[ÇAP mm]]/14.50377 | O28: 5.5 | P28: =2*Tablo244[[#This Row],[SMYS Psi]]*Tablo244[[#This Row],[Et Kalınlığı 5]]/Tablo244[[#This Row],[ÇAP mm]]/14.50377 | Q28: =Tablo244[[#This Row],[ÇAP mm]]+1.6 | R28: =Tablo244[[#This Row],[ÇAP mm]]-0.4 | S28: =Tablo244[[#This Row],[ÇAP mm]]*1.0075 | T28: =Tablo244[[#This Row],[ÇAP mm]]*0.9925 | X28: =Tablo244[[#This Row],[ÇAP mm]]/Tablo244[[#This Row],[Et Kalınlığı 4]] | Y28: =Tablo244[[#This Row],[ÇAP mm]]/Tablo244[[#This Row],[Et Kalınlığı 5]] | AF28: =IF(Tablo244[[#This Row],[ÇAP mm]]/Tablo244[[#This Row],[Et Kalınlığı 4]]<75,Tablo244[[#This Row],[ÇAP mm]]*0.015/2,"Anlaşmaya bağlıdır.") | AG28: =IF(Tablo244[[#This Row],[ÇAP mm]]/Tablo244[[#This Row],[Et Kalınlığı 4]]<75,Tablo244[[#This Row],[ÇAP mm]]*0.02,"Anlaşmaya bağlıdır.") | AH28: =IF(Tablo244[[#This Row],[ÇAP mm]]/Tablo244[[#This Row],[Et Kalınlığı 4]]<75,Tablo244[[#This Row],[ÇAP mm]]*0.015/2,"Anlaşmaya bağlıdır.") | AI28: =IF(Tablo244[[#This Row],[ÇAP mm]]/Tablo244[[#This Row],[Et Kalınlığı 5]]<75,Tablo244[[#This Row],[ÇAP mm]]*0.02,"Anlaşmaya bağlıdır.") | AP28: =IF(40*Tablo244[[#This Row],[Et Kalınlığı 4]]<485,Tablo244[[#This Row],[Et Kalınlığı 4]]*40,485) | AQ28: =1940*POWER(ROUND(Tablo151[[#This Row],[Axc mm24]],-1),0.2)/POWER(Tablo244[[#This Row],[Tensile Mpa]],0.9) | AR28: =IF(40*Tablo244[[#This Row],[Et Kalınlığı 5]]<485,Tablo244[[#This Row],[Et Kalınlığı 4]]*40,485) | AS28: =1940*POWER(ROUND(Tablo151[[#This Row],[Axc mm25]],-1),0.2)/POWER(Tablo244[[#This Row],[Tensile Mpa]],0.9)
B29: 4" | C29: 114.3 | D29: GRADE B | E29: 35500 | F29: 415 | M29: 6 | N29: =2*Tablo244[[#This Row],[SMYS Psi]]*Tablo244[[#This Row],[Et Kalınlığı 4]]/Tablo244[[#This Row],[ÇAP mm]]/14.50377 | O29: 6 | P29: =2*Tablo244[[#This Row],[SMYS Psi]]*Tablo244[[#This Row],[Et Kalınlığı 5]]/Tablo244[[#This Row],[ÇAP mm]]/14.50377 | Q29: =Tablo244[[#This Row],[ÇAP mm]]+1.6 | R29: =Tablo244[[#This Row],[ÇAP mm]]-0.4 | S29: =Tablo244[[#This Row],[ÇAP mm]]*1.0075 | T29: =Tablo244[[#This Row],[ÇAP mm]]*0.9925 | X29: =Tablo244[[#This Row],[ÇAP mm]]/Tablo244[[#This Row],[Et Kalınlığı 4]] | Y29: =Tablo244[[#This Row],[ÇAP mm]]/Tablo244[[#This Row],[Et Kalınlığı 5]] | AF29: =IF(Tablo244[[#This Row],[ÇAP mm]]/Tablo244[[#This Row],[Et Kalınlığı 4]]<75,Tablo244[[#This Row],[ÇAP mm]]*0.015/2,"Anlaşmaya bağlıdır.") | AG29: =IF(Tablo244[[#This Row],[ÇAP mm]]/Tablo244[[#This Row],[Et Kalınlığı 4]]<75,Tablo244[[#This Row],[ÇAP mm]]*0.02,"Anlaşmaya bağlıdır.") | AH29: =IF(Tablo244[[#This Row],[ÇAP mm]]/Tablo244[[#This Row],[Et Kalınlığı 4]]<75,Tablo244[[#This Row],[ÇAP mm]]*0.015/2,"Anlaşmaya bağlıdır.") | AI29: =IF(Tablo244[[#This Row],[ÇAP mm]]/Tablo244[[#This Row],[Et Kalınlığı 5]]<75,Tablo244[[#This Row],[ÇAP mm]]*0.02,"Anlaşmaya bağlıdır.") | AP29: =IF(40*Tablo244[[#This Row],[Et Kalınlığı 4]]<485,Tablo244[[#This Row],[Et Kalınlığı 4]]*40,485) | AQ29: =1940*POWER(ROUND(Tablo151[[#This Row],[Axc mm24]],-1),0.2)/POWER(Tablo244[[#This Row],[Tensile Mpa]],0.9) | AR29: =IF(40*Tablo244[[#This Row],[Et Kalınlığı 5]]<485,Tablo244[[#This Row],[Et Kalınlığı 4]]*40,485) | AS29: =1940*POWER(ROUND(Tablo151[[#This Row],[Axc mm25]],-1),0.2)/POWER(Tablo244[[#This Row],[Tensile Mpa]],0.9)
B30: 5" | C30: 141.3 | D30: GRADE B | E30: 35500 | F30: 415 | M30: 6.6 | N30: =2*Tablo244[[#This Row],[SMYS Psi]]*Tablo244[[#This Row],[Et Kalınlığı 4]]/Tablo244[[#This Row],[ÇAP mm]]/14.50377 | O30: 7.1 | P30: =2*Tablo244[[#This Row],[SMYS Psi]]*Tablo244[[#This Row],[Et Kalınlığı 5]]/Tablo244[[#This Row],[ÇAP mm]]/14.50377 | Q30: =Tablo244[[#This Row],[ÇAP mm]]+1.6 | R30: =Tablo244[[#This Row],[ÇAP mm]]-0.4 | S30: =Tablo244[[#This Row],[ÇAP mm]]*1.0075 | T30: =Tablo244[[#This Row],[ÇAP mm]]*0.9925 | X30: =Tablo244[[#This Row],[ÇAP mm]]/Tablo244[[#This Row],[Et Kalınlığı 4]] | Y30: =Tablo244[[#This Row],[ÇAP mm]]/Tablo244[[#This Row],[Et Kalınlığı 5]] | AF30: =IF(Tablo244[[#This Row],[ÇAP mm]]/Tablo244[[#This Row],[Et Kalınlığı 4]]<75,Tablo244[[#This Row],[ÇAP mm]]*0.015/2,"Anlaşmaya bağlıdır.") | AG30: =IF(Tablo244[[#This Row],[ÇAP mm]]/Tablo244[[#This Row],[Et Kalınlığı 4]]<75,Tablo244[[#This Row],[ÇAP mm]]*0.02,"Anlaşmaya bağlıdır.") | AH30: =IF(Tablo244[[#This Row],[ÇAP mm]]/Tablo244[[#This Row],[Et Kalınlığı 5]]<75,Tablo244[[#This Row],[ÇAP mm]]*0.015/2,"Anlaşmaya bağlıdır.") | AI30: =IF(Tablo244[[#This Row],[ÇAP mm]]/Tablo244[[#This Row],[Et Kalınlığı 5]]<75,Tablo244[[#This Row],[ÇAP mm]]*0.02,"Anlaşmaya bağlıdır.") | AP30: =IF(40*Tablo244[[#This Row],[Et Kalınlığı 4]]<485,Tablo244[[#This Row],[Et Kalınlığı 4]]*40,485) | AQ30: =1940*POWER(ROUND(Tablo151[[#This Row],[Axc mm24]],-1),0.2)/POWER(Tablo244[[#This Row],[Tensile Mpa]],0.9) | AR30: =IF(40*Tablo244[[#This Row],[Et Kalınlığı 5]]<485,Tablo244[[#This Row],[Et Kalınlığı 4]]*40,485) | AS30: =1940*POWER(ROUND(Tablo151[[#This Row],[Axc mm25]],-1),0.2)/POWER(Tablo244[[#This Row],[Tensile Mpa]],0.9)
B31: 6" | C31: 168.3 | D31: X42 | E31: 42100 | F31: 415 | G31: 5.2 | H31: =2*Tablo244[[#This Row],[SMYS Psi]]*Tablo244[[#This Row],[Et Kalınlığı ]]/Tablo244[[#This Row],[ÇAP mm]]/14.50377 | I31: 5.2 | J31: =2*Tablo244[[#This Row],[SMYS Psi]]*Tablo244[[#This Row],[Et Kalınlığı 2]]/Tablo244[[#This Row],[ÇAP mm]]/14.50377 | K31: 5.2 | L31: =2*Tablo244[[#This Row],[SMYS Psi]]*Tablo244[[#This Row],[Et Kalınlığı 3]]/Tablo244[[#This Row],[ÇAP mm]]/14.50377 | M31: 6.4 | N31: =2*Tablo244[[#This Row],[SMYS Psi]]*Tablo244[[#This Row],[Et Kalınlığı 4]]/Tablo244[[#This Row],[ÇAP mm]]/14.50377 | O31: 6.4 | P31: =2*Tablo244[[#This Row],[SMYS Psi]]*Tablo244[[#This Row],[Et Kalınlığı 5]]/Tablo244[[#This Row],[ÇAP mm]]/14.50377 | Q31: =IF(Tablo244[[#This Row],[ÇAP mm]]*0.005-1.6<0,Tablo244[[#This Row],[ÇAP mm]]*1.005,Tablo244[[#This Row],[ÇAP mm]]+1.6) | R31: =IF(Tablo244[[#This Row],[ÇAP mm]]*0.005-1.6<0,Tablo244[[#This Row],[ÇAP mm]]*0.995,Tablo244[[#This Row],[ÇAP mm]]-1.6) | S31: =IF(Tablo244[[#This Row],[ÇAP mm]]*0.0075-3.2<0,Tablo244[[#This Row],[ÇAP mm]]*1.0075,Tablo244[[#This Row],[ÇAP mm]]+3.2) | T31: =IF(Tablo244[[#This Row],[ÇAP mm]]*0.005-3.2<0,Tablo244[[#This Row],[ÇAP mm]]*0.9925,Tablo244[[#This Row],[ÇAP mm]]-3.2) | U31: =Tablo244[[#This Row],[ÇAP mm]]/Tablo244[[#This Row],[Et Kalınlığı ]] | V31: =Tablo244[[#This Row],[ÇAP mm]]/Tablo244[[#This Row],[Et Kalınlığı 2]] | W31: =Tablo244[[#This Row],[ÇAP mm]]/Tablo244[[#This Row],[Et Kalınlığı 3]] | X31: =Tablo244[[#This Row],[ÇAP mm]]/Tablo244[[#This Row],[Et Kalınlığı 4]] | Y31: =Tablo244[[#This Row],[ÇAP mm]]/Tablo244[[#This Row],[Et Kalınlığı 5]] | Z31: =IF(Tablo244[[#This Row],[ÇAP mm]]/Tablo244[[#This Row],[Et Kalınlığı ]]<75,Tablo244[[#This Row],[ÇAP mm]]*0.015/2,"Anlaşmaya bağlıdır.") | AA31: =IF(Tablo244[[#This Row],[ÇAP mm]]/Tablo244[[#This Row],[Et Kalınlığı ]]<75,Tablo244[[#This Row],[ÇAP mm]]*0.02,"Anlaşmaya bağlıdır.") | AB31: =IF(Tablo244[[#This Row],[ÇAP mm]]/Tablo244[[#This Row],[Et Kalınlığı ]]<75,Tablo244[[#This Row],[ÇAP mm]]*0.015/2,"Anlaşmaya bağlıdır.") | AC31: =IF(Tablo244[[#This Row],[ÇAP mm]]/Tablo244[[#This Row],[Et Kalınlığı 2]]<75,Tablo244[[#This Row],[ÇAP mm]]*0.02,"Anlaşmaya bağlıdır.") | AD31: =IF(Tablo244[[#This Row],[ÇAP mm]]/Tablo244[[#This Row],[Et Kalınlığı ]]<75,Tablo244[[#This Row],[ÇAP mm]]*0.015/2,"Anlaşmaya bağlıdır.") | AE31: =IF(Tablo244[[#This Row],[ÇAP mm]]/Tablo244[[#This Row],[Et Kalınlığı 3]]<75,Tablo244[[#This Row],[ÇAP mm]]*0.02,"Anlaşmaya bağlıdır.") | AF31: =IF(Tablo244[[#This Row],[ÇAP mm]]/Tablo244[[#This Row],[Et Kalınlığı 4]]<75,Tablo244[[#This Row],[ÇAP mm]]*0.015/2,"Anlaşmaya bağlıdır.") | AG31: =IF(Tablo244[[#This Row],[ÇAP mm]]/Tablo244[[#This Row],[Et Kalınlığı 4]]<75,Tablo244[[#This Row],[ÇAP mm]]*0.02,"Anlaşmaya bağlıdır.") | AH31: =IF(Tablo244[[#This Row],[ÇAP mm]]/Tablo244[[#This Row],[Et Kalınlığı 5]]<75,Tablo244[[#This Row],[ÇAP mm]]*0.015/2,"Anlaşmaya bağlıdır.") | AI31: =IF(Tablo244[[#This Row],[ÇAP mm]]/Tablo244[[#This Row],[Et Kalınlığı 5]]<75,Tablo244[[#This Row],[ÇAP mm]]*0.02,"Anlaşmaya bağlıdır.") | AJ31: =IF(40*Tablo244[[#This Row],[Et Kalınlığı ]]<485,Tablo244[[#This Row],[Et Kalınlığı ]]*40,485) | AK31: =1940*POWER(ROUND(AJ31,-1),0.2)/POWER(Tablo244[[#This Row],[Tensile Mpa]],0.9) | AL31: =IF(40*Tablo244[[#This Row],[Et Kalınlığı 2]]<485,Tablo244[[#This Row],[Et Kalınlığı ]]*40,485) | AM31: =1940*POWER(ROUND(Tablo151[[#This Row],[Axc mm22]],-1),0.2)/POWER(Tablo244[[#This Row],[Tensile Mpa]],0.9) | AN31: =IF(40*Tablo244[[#This Row],[Et Kalınlığı 3]]<485,Tablo244[[#This Row],[Et Kalınlığı ]]*40,485) | AO31: =1940*POWER(ROUND(Tablo151[[#This Row],[Axc mm23]],-1),0.2)/POWER(Tablo244[[#This Row],[Tensile Mpa]],0.9) | AP31: =IF(40*Tablo244[[#This Row],[Et Kalınlığı 4]]<485,Tablo244[[#This Row],[Et Kalınlığı 4]]*40,485) | AQ31: =1940*POWER(ROUND(Tablo151[[#This Row],[Axc mm24]],-1),0.2)/POWER(Tablo244[[#This Row],[Tensile Mpa]],0.9) | AR31: =IF(40*Tablo244[[#This Row],[Et Kalınlığı 5]]<485,Tablo244[[#This Row],[Et Kalınlığı 4]]*40,485) | AS31: =1940*POWER(ROUND(Tablo151[[#This Row],[Axc mm25]],-1),0.2)/POWER(Tablo244[[#This Row],[Tensile Mpa]],0.9)
B32: 8" | C32: 219.1 | D32: X42 | E32: 42100 | F32: 415 | G32: 5.2 | H32: =2*Tablo244[[#This Row],[SMYS Psi]]*Tablo244[[#This Row],[Et Kalınlığı ]]/Tablo244[[#This Row],[ÇAP mm]]/14.50377 | I32: 5.2 | J32: =2*Tablo244[[#This Row],[SMYS Psi]]*Tablo244[[#This Row],[Et Kalınlığı 2]]/Tablo244[[#This Row],[ÇAP mm]]/14.50377 | K32: 6.4 | L32: =2*Tablo244[[#This Row],[SMYS Psi]]*Tablo244[[#This Row],[Et Kalınlığı 3]]/Tablo244[[#This Row],[ÇAP mm]]/14.50377 | M32: 7.9 | N32: =2*Tablo244[[#This Row],[SMYS Psi]]*Tablo244[[#This Row],[Et Kalınlığı 4]]/Tablo244[[#This Row],[ÇAP mm]]/14.50377 | O32: 7.9 | P32: =2*Tablo244[[#This Row],[SMYS Psi]]*Tablo244[[#This Row],[Et Kalınlığı 5]]/Tablo244[[#This Row],[ÇAP mm]]/14.50377 | Q32: =IF(Tablo244[[#This Row],[ÇAP mm]]*0.005-1.6<0,Tablo244[[#This Row],[ÇAP mm]]*1.005,Tablo244[[#This Row],[ÇAP mm]]+1.6) | R32: =IF(Tablo244[[#This Row],[ÇAP mm]]*0.005-1.6<0,Tablo244[[#This Row],[ÇAP mm]]*0.995,Tablo244[[#This Row],[ÇAP mm]]-1.6) | S32: =IF(Tablo244[[#This Row],[ÇAP mm]]*0.0075-3.2<0,Tablo244[[#This Row],[ÇAP mm]]*1.0075,Tablo244[[#This Row],[ÇAP mm]]+3.2) | T32: =IF(Tablo244[[#This Row],[ÇAP mm]]*0.005-3.2<0,Tablo244[[#This Row],[ÇAP mm]]*0.9925,Tablo244[[#This Row],[ÇAP mm]]-3.2) | U32: =Tablo244[[#This Row],[ÇAP mm]]/Tablo244[[#This Row],[Et Kalınlığı ]] | V32: =Tablo244[[#This Row],[ÇAP mm]]/Tablo244[[#This Row],[Et Kalınlığı 2]] | W32: =Tablo244[[#This Row],[ÇAP mm]]/Tablo244[[#This Row],[Et Kalınlığı 3]] | X32: =Tablo244[[#This Row],[ÇAP mm]]/Tablo244[[#This Row],[Et Kalınlığı 4]] | Y32: =Tablo244[[#This Row],[ÇAP mm]]/Tablo244[[#This Row],[Et Kalınlığı 5]] | Z32: =Tablo244[[#This Row],[ÇAP mm]]*0.015/2 | AA32: =Tablo244[[#This Row],[ÇAP mm]]*0.02 | AB32: =Tablo244[[#This Row],[ÇAP mm]]*0.015/2 | AC32: =Tablo244[[#This Row],[ÇAP mm]]*0.02 | AD32: =Tablo244[[#This Row],[ÇAP mm]]*0.015/2 | AE32: =Tablo244[[#This Row],[ÇAP mm]]*0.02 | AF32: =IF(Tablo244[[#This Row],[ÇAP mm]]/Tablo244[[#This Row],[Et Kalınlığı 4]]<75,Tablo244[[#This Row],[ÇAP mm]]*0.015/2,"Anlaşmaya bağlıdır.") | AG32: =Tablo244[[#This Row],[ÇAP mm]]*0.02 | AH32: =IF(Tablo244[[#This Row],[ÇAP mm]]/Tablo244[[#This Row],[Et Kalınlığı 5]]<75,Tablo244[[#This Row],[ÇAP mm]]*0.015/2,"Anlaşmaya bağlıdır.") | AI32: =Tablo244[[#This Row],[ÇAP mm]]*0.02 | AJ32: =IF(40*Tablo244[[#This Row],[Et Kalınlığı ]]<485,Tablo244[[#This Row],[Et Kalınlığı ]]*40,485) | AK32: =1940*POWER(ROUND(AJ32,-1),0.2)/POWER(Tablo244[[#This Row],[Tensile Mpa]],0.9) | AL32: =IF(40*Tablo244[[#This Row],[Et Kalınlığı 2]]<485,Tablo244[[#This Row],[Et Kalınlığı ]]*40,485) | AM32: =1940*POWER(ROUND(Tablo151[[#This Row],[Axc mm22]],-1),0.2)/POWER(Tablo244[[#This Row],[Tensile Mpa]],0.9) | AN32: =IF(40*Tablo244[[#This Row],[Et Kalınlığı 3]]<485,Tablo244[[#This Row],[Et Kalınlığı ]]*40,485) | AO32: =1940*POWER(ROUND(Tablo151[[#This Row],[Axc mm23]],-1),0.2)/POWER(Tablo244[[#This Row],[Tensile Mpa]],0.9) | AP32: =IF(40*Tablo244[[#This Row],[Et Kalınlığı 4]]<485,Tablo244[[#This Row],[Et Kalınlığı 4]]*40,485) | AQ32: =1940*POWER(ROUND(Tablo151[[#This Row],[Axc mm24]],-1),0.2)/POWER(Tablo244[[#This Row],[Tensile Mpa]],0.9) | AR32: =IF(40*Tablo244[[#This Row],[Et Kalınlığı 5]]<485,Tablo244[[#This Row],[Et Kalınlığı 4]]*40,485) | AS32: =1940*POWER(ROUND(Tablo151[[#This Row],[Axc mm25]],-1),0.2)/POWER(Tablo244[[#This Row],[Tensile Mpa]],0.9)
B33: 10" | C33: 273.1 | D33: X46 | E33: 46400 | F33: 435 | G33: 5.2 | H33: =2*Tablo244[[#This Row],[SMYS Psi]]*Tablo244[[#This Row],[Et Kalınlığı ]]/Tablo244[[#This Row],[ÇAP mm]]/14.50377 | I33: 5.6 | J33: =2*Tablo244[[#This Row],[SMYS Psi]]*Tablo244[[#This Row],[Et Kalınlığı 2]]/Tablo244[[#This Row],[ÇAP mm]]/14.50377 | K33: 7.1 | L33: =2*Tablo244[[#This Row],[SMYS Psi]]*Tablo244[[#This Row],[Et Kalınlığı 3]]/Tablo244[[#This Row],[ÇAP mm]]/14.50377 | M33: 8.7 | N33: =2*Tablo244[[#This Row],[SMYS Psi]]*Tablo244[[#This Row],[Et Kalınlığı 4]]/Tablo244[[#This Row],[ÇAP mm]]/14.50377 | O33: 8.7 | P33: =2*Tablo244[[#This Row],[SMYS Psi]]*Tablo244[[#This Row],[Et Kalınlığı 5]]/Tablo244[[#This Row],[ÇAP mm]]/14.50377 | Q33: =IF(Tablo244[[#This Row],[ÇAP mm]]*0.005-1.6<0,Tablo244[[#This Row],[ÇAP mm]]*1.005,Tablo244[[#This Row],[ÇAP mm]]+1.6) | R33: =IF(Tablo244[[#This Row],[ÇAP mm]]*0.005-1.6<0,Tablo244[[#This Row],[ÇAP mm]]*0.995,Tablo244[[#This Row],[ÇAP mm]]-1.6) | S33: =IF(Tablo244[[#This Row],[ÇAP mm]]*0.0075-3.2<0,Tablo244[[#This Row],[ÇAP mm]]*1.0075,Tablo244[[#This Row],[ÇAP mm]]+3.2) | T33: =IF(Tablo244[[#This Row],[ÇAP mm]]*0.005-3.2<0,Tablo244[[#This Row],[ÇAP mm]]*0.9925,Tablo244[[#This Row],[ÇAP mm]]-3.2) | U33: =Tablo244[[#This Row],[ÇAP mm]]/Tablo244[[#This Row],[Et Kalınlığı ]] | V33: =Tablo244[[#This Row],[ÇAP mm]]/Tablo244[[#This Row],[Et Kalınlığı 2]] | W33: =Tablo244[[#This Row],[ÇAP mm]]/Tablo244[[#This Row],[Et Kalınlığı 3]] | X33: =Tablo244[[#This Row],[ÇAP mm]]/Tablo244[[#This Row],[Et Kalınlığı 4]] | Y33: =Tablo244[[#This Row],[ÇAP mm]]/Tablo244[[#This Row],[Et Kalınlığı 5]] | Z33: =Tablo244[[#This Row],[ÇAP mm]]*0.015/2 | AA33: =Tablo244[[#This Row],[ÇAP mm]]*0.02 | AB33: =Tablo244[[#This Row],[ÇAP mm]]*0.015/2 | AC33: =Tablo244[[#This Row],[ÇAP mm]]*0.02 | AD33: =Tablo244[[#This Row],[ÇAP mm]]*0.015/2 | AE33: =Tablo244[[#This Row],[ÇAP mm]]*0.02 | AF33: =IF(Tablo244[[#This Row],[ÇAP mm]]/Tablo244[[#This Row],[Et Kalınlığı 4]]<75,Tablo244[[#This Row],[ÇAP mm]]*0.015/2,"Anlaşmaya bağlıdır.") | AG33: =Tablo244[[#This Row],[ÇAP mm]]*0.02 | AH33: =IF(Tablo244[[#This Row],[ÇAP mm]]/Tablo244[[#This Row],[Et Kalınlığı 5]]<75,Tablo244[[#This Row],[ÇAP mm]]*0.015/2,"Anlaşmaya bağlıdır.") | AI33: =Tablo244[[#This Row],[ÇAP mm]]*0.02 | AJ33: =IF(40*Tablo244[[#This Row],[Et Kalınlığı ]]<485,Tablo244[[#This Row],[Et Kalınlığı ]]*40,485) | AK33: =1940*POWER(ROUND(AJ33,-1),0.2)/POWER(Tablo244[[#This Row],[Tensile Mpa]],0.9) | AL33: =IF(40*Tablo244[[#This Row],[Et Kalınlığı 2]]<485,Tablo244[[#This Row],[Et Kalınlığı ]]*40,485) | AM33: =1940*POWER(ROUND(Tablo151[[#This Row],[Axc mm22]],-1),0.2)/POWER(Tablo244[[#This Row],[Tensile Mpa]],0.9) | AN33: =IF(40*Tablo244[[#This Row],[Et Kalınlığı 3]]<485,Tablo244[[#This Row],[Et Kalınlığı ]]*40,485) | AO33: =1940*POWER(ROUND(Tablo151[[#This Row],[Axc mm23]],-1),0.2)/POWER(Tablo244[[#This Row],[Tensile Mpa]],0.9) | AP33: =IF(40*Tablo244[[#This Row],[Et Kalınlığı 4]]<485,Tablo244[[#This Row],[Et Kalınlığı 4]]*40,485) | AQ33: =1940*POWER(ROUND(Tablo151[[#This Row],[Axc mm24]],-1),0.2)/POWER(Tablo244[[#This Row],[Tensile Mpa]],0.9) | AR33: =IF(40*Tablo244[[#This Row],[Et Kalınlığı 5]]<485,Tablo244[[#This Row],[Et Kalınlığı 4]]*40,485) | AS33: =1940*POWER(ROUND(Tablo151[[#This Row],[Axc mm25]],-1),0.2)/POWER(Tablo244[[#This Row],[Tensile Mpa]],0.9)
B34: 12" | C34: 323.9 | D34: X52 | E34: 52200 | F34: 460 | G34: 5.2 | H34: =2*Tablo244[[#This Row],[SMYS Psi]]*Tablo244[[#This Row],[Et Kalınlığı ]]/Tablo244[[#This Row],[ÇAP mm]]/14.50377 | I34: 6.4 | J34: =2*Tablo244[[#This Row],[SMYS Psi]]*Tablo244[[#This Row],[Et Kalınlığı 2]]/Tablo244[[#This Row],[ÇAP mm]]/14.50377 | K34: 7.1 | L34: =2*Tablo244[[#This Row],[SMYS Psi]]*Tablo244[[#This Row],[Et Kalınlığı 3]]/Tablo244[[#This Row],[ÇAP mm]]/14.50377 | M34: 8.4 | N34: =2*Tablo244[[#This Row],[SMYS Psi]]*Tablo244[[#This Row],[Et Kalınlığı 4]]/Tablo244[[#This Row],[ÇAP mm]]/14.50377 | O34: 9.5 | P34: =2*Tablo244[[#This Row],[SMYS Psi]]*Tablo244[[#This Row],[Et Kalınlığı 5]]/Tablo244[[#This Row],[ÇAP mm]]/14.50377 | Q34: =IF(Tablo244[[#This Row],[ÇAP mm]]*0.005-1.6<0,Tablo244[[#This Row],[ÇAP mm]]*1.005,Tablo244[[#This Row],[ÇAP mm]]+1.6) | R34: =IF(Tablo244[[#This Row],[ÇAP mm]]*0.005-1.6<0,Tablo244[[#This Row],[ÇAP mm]]*0.995,Tablo244[[#This Row],[ÇAP mm]]-1.6) | S34: =IF(Tablo244[[#This Row],[ÇAP mm]]*0.0075-3.2<0,Tablo244[[#This Row],[ÇAP mm]]*1.0075,Tablo244[[#This Row],[ÇAP mm]]+3.2) | T34: =IF(Tablo244[[#This Row],[ÇAP mm]]*0.005-3.2<0,Tablo244[[#This Row],[ÇAP mm]]*0.9925,Tablo244[[#This Row],[ÇAP mm]]-3.2) | U34: =Tablo244[[#This Row],[ÇAP mm]]/Tablo244[[#This Row],[Et Kalınlığı ]] | V34: =Tablo244[[#This Row],[ÇAP mm]]/Tablo244[[#This Row],[Et Kalınlığı 2]] | W34: =Tablo244[[#This Row],[ÇAP mm]]/Tablo244[[#This Row],[Et Kalınlığı 3]] | X34: =Tablo244[[#This Row],[ÇAP mm]]/Tablo244[[#This Row],[Et Kalınlığı 4]] | Y34: =Tablo244[[#This Row],[ÇAP mm]]/Tablo244[[#This Row],[Et Kalınlığı 5]] | Z34: =Tablo244[[#This Row],[ÇAP mm]]*0.015/2 | AA34: =Tablo244[[#This Row],[ÇAP mm]]*0.02 | AB34: =Tablo244[[#This Row],[ÇAP mm]]*0.015/2 | AC34: =Tablo244[[#This Row],[ÇAP mm]]*0.02 | AD34: =Tablo244[[#This Row],[ÇAP mm]]*0.015/2 | AE34: =Tablo244[[#This Row],[ÇAP mm]]*0.02 | AF34: =IF(Tablo244[[#This Row],[ÇAP mm]]/Tablo244[[#This Row],[Et Kalınlığı 4]]<75,Tablo244[[#This Row],[ÇAP mm]]*0.015/2,"Anlaşmaya bağlıdır.") | AG34: =Tablo244[[#This Row],[ÇAP mm]]*0.02 | AH34: =IF(Tablo244[[#This Row],[ÇAP mm]]/Tablo244[[#This Row],[Et Kalınlığı 5]]<75,Tablo244[[#This Row],[ÇAP mm]]*0.015/2,"Anlaşmaya bağlıdır.") | AI34: =Tablo244[[#This Row],[ÇAP mm]]*0.02 | AJ34: =IF(40*Tablo244[[#This Row],[Et Kalınlığı ]]<485,Tablo244[[#This Row],[Et Kalınlığı ]]*40,485) | AK34: =1940*POWER(ROUND(AJ34,-1),0.2)/POWER(Tablo244[[#This Row],[Tensile Mpa]],0.9) | AL34: =IF(40*Tablo244[[#This Row],[Et Kalınlığı 2]]<485,Tablo244[[#This Row],[Et Kalınlığı ]]*40,485) | AM34: =1940*POWER(ROUND(Tablo151[[#This Row],[Axc mm22]],-1),0.2)/POWER(Tablo244[[#This Row],[Tensile Mpa]],0.9) | AN34: =IF(40*Tablo244[[#This Row],[Et Kalınlığı 3]]<485,Tablo244[[#This Row],[Et Kalınlığı ]]*40,485) | AO34: =1940*POWER(ROUND(Tablo151[[#This Row],[Axc mm23]],-1),0.2)/POWER(Tablo244[[#This Row],[Tensile Mpa]],0.9) | AP34: =IF(40*Tablo244[[#This Row],[Et Kalınlığı 4]]<485,Tablo244[[#This Row],[Et Kalınlığı 4]]*40,485) | AQ34: =1940*POWER(ROUND(Tablo151[[#This Row],[Axc mm24]],-1),0.2)/POWER(Tablo244[[#This Row],[Tensile Mpa]],0.9) | AR34: =IF(40*Tablo244[[#This Row],[Et Kalınlığı 5]]<485,Tablo244[[#This Row],[Et Kalınlığı 4]]*40,485) | AS34: =1940*POWER(ROUND(Tablo151[[#This Row],[Axc mm25]],-1),0.2)/POWER(Tablo244[[#This Row],[Tensile Mpa]],0.9)
B35: 14" | C35: 355.6 | D35: X52 | E35: 52200 | F35: 460 | G35: 5.2 | H35: =2*Tablo244[[#This Row],[SMYS Psi]]*Tablo244[[#This Row],[Et Kalınlığı ]]/Tablo244[[#This Row],[ÇAP mm]]/14.50377 | I35: 6.4 | J35: =2*Tablo244[[#This Row],[SMYS Psi]]*Tablo244[[#This Row],[Et Kalınlığı 2]]/Tablo244[[#This Row],[ÇAP mm]]/14.50377 | K35: 7.9 | L35: =2*Tablo244[[#This Row],[SMYS Psi]]*Tablo244[[#This Row],[Et Kalınlığı 3]]/Tablo244[[#This Row],[ÇAP mm]]/14.50377 | M35: 9.5 | N35: =2*Tablo244[[#This Row],[SMYS Psi]]*Tablo244[[#This Row],[Et Kalınlığı 4]]/Tablo244[[#This Row],[ÇAP mm]]/14.50377 | O35: 10.3 | P35: =2*Tablo244[[#This Row],[SMYS Psi]]*Tablo244[[#This Row],[Et Kalınlığı 5]]/Tablo244[[#This Row],[ÇAP mm]]/14.50377 | Q35: =IF(Tablo244[[#This Row],[ÇAP mm]]*0.005-1.6<0,Tablo244[[#This Row],[ÇAP mm]]*1.005,Tablo244[[#This Row],[ÇAP mm]]+1.6) | R35: =IF(Tablo244[[#This Row],[ÇAP mm]]*0.005-1.6<0,Tablo244[[#This Row],[ÇAP mm]]*0.995,Tablo244[[#This Row],[ÇAP mm]]-1.6) | S35: =IF(Tablo244[[#This Row],[ÇAP mm]]*0.0075-3.2<0,Tablo244[[#This Row],[ÇAP mm]]*1.0075,Tablo244[[#This Row],[ÇAP mm]]+3.2) | T35: =IF(Tablo244[[#This Row],[ÇAP mm]]*0.005-3.2<0,Tablo244[[#This Row],[ÇAP mm]]*0.9925,Tablo244[[#This Row],[ÇAP mm]]-3.2) | U35: =Tablo244[[#This Row],[ÇAP mm]]/Tablo244[[#This Row],[Et Kalınlığı ]] | V35: =Tablo244[[#This Row],[ÇAP mm]]/Tablo244[[#This Row],[Et Kalınlığı 2]] | W35: =Tablo244[[#This Row],[ÇAP mm]]/Tablo244[[#This Row],[Et Kalınlığı 3]] | X35: =Tablo244[[#This Row],[ÇAP mm]]/Tablo244[[#This Row],[Et Kalınlığı 4]] | Y35: =Tablo244[[#This Row],[ÇAP mm]]/Tablo244[[#This Row],[Et Kalınlığı 5]] | Z35: =Tablo244[[#This Row],[ÇAP mm]]*0.015/2 | AA35: =Tablo244[[#This Row],[ÇAP mm]]*0.02 | AB35: =Tablo244[[#This Row],[ÇAP mm]]*0.015/2 | AC35: =Tablo244[[#This Row],[ÇAP mm]]*0.02 | AD35: =Tablo244[[#This Row],[ÇAP mm]]*0.015/2 | AE35: =Tablo244[[#This Row],[ÇAP mm]]*0.02 | AF35: =IF(Tablo244[[#This Row],[ÇAP mm]]/Tablo244[[#This Row],[Et Kalınlığı 4]]<75,Tablo244[[#This Row],[ÇAP mm]]*0.015/2,"Anlaşmaya bağlıdır.") | AG35: =Tablo244[[#This Row],[ÇAP mm]]*0.02 | AH35: =IF(Tablo244[[#This Row],[ÇAP mm]]/Tablo244[[#This Row],[Et Kalınlığı 5]]<75,Tablo244[[#This Row],[ÇAP mm]]*0.015/2,"Anlaşmaya bağlıdır.") | AI35: =Tablo244[[#This Row],[ÇAP mm]]*0.02 | AJ35: =IF(40*Tablo244[[#This Row],[Et Kalınlığı ]]<485,Tablo244[[#This Row],[Et Kalınlığı ]]*40,485) | AK35: =1940*POWER(ROUND(AJ35,-1),0.2)/POWER(Tablo244[[#This Row],[Tensile Mpa]],0.9) | AL35: =IF(40*Tablo244[[#This Row],[Et Kalınlığı 2]]<485,Tablo244[[#This Row],[Et Kalınlığı ]]*40,485) | AM35: =1940*POWER(ROUND(Tablo151[[#This Row],[Axc mm22]],-1),0.2)/POWER(Tablo244[[#This Row],[Tensile Mpa]],0.9) | AN35: =IF(40*Tablo244[[#This Row],[Et Kalınlığı 3]]<485,Tablo244[[#This Row],[Et Kalınlığı ]]*40,485) | AO35: =1940*POWER(ROUND(Tablo151[[#This Row],[Axc mm23]],-1),0.2)/POWER(Tablo244[[#This Row],[Tensile Mpa]],0.9) | AP35: =IF(40*Tablo244[[#This Row],[Et Kalınlığı 4]]<485,Tablo244[[#This Row],[Et Kalınlığı 4]]*40,485) | AQ35: =1940*POWER(ROUND(Tablo151[[#This Row],[Axc mm24]],-1),0.2)/POWER(Tablo244[[#This Row],[Tensile Mpa]],0.9) | AR35: =IF(40*Tablo244[[#This Row],[Et Kalınlığı 5]]<485,Tablo244[[#This Row],[Et Kalınlığı 4]]*40,485) | AS35: =1940*POWER(ROUND(Tablo151[[#This Row],[Axc mm25]],-1),0.2)/POWER(Tablo244[[#This Row],[Tensile Mpa]],0.9)
